2023-12-15 21:58:21.618 WARNING (SyncWorker_1) [homeassistant.loader] We found a custom integration xiaomi_miot which has not been tested by Home Assistant. This component might cause stability problems, be sure to disable it if you experience issues with Home Assistant
2023-12-15 21:58:25.681 WARNING (SyncWorker_5) [miio.device] Found an unsupported model 'lumi.gateway.mgl001' for class 'Gateway'. If this is working for you, please open an issue at https://github.com/rytilahti/python-miio/
2023-12-15 21:58:25.892 ERROR (MainThread) [homeassistant.components.github] Bad credentials
Traceback (most recent call last):
  File "/usr/src/homeassistant/homeassistant/components/github/coordinator.py", line 128, in _async_update_data
    response = await self._client.graphql(
               ^^^^^^^^^^^^^^^^^^^^^^^^^^^
  File "/usr/local/lib/python3.11/site-packages/aiogithubapi/github.py", line 239, in graphql
    return await self._client.async_call_api(
           ^^^^^^^^^^^^^^^^^^^^^^^^^^^^^^^^^^
  File "/usr/local/lib/python3.11/site-packages/aiogithubapi/client.py", line 146, in async_call_api
    raise exception(message or response.data)
aiogithubapi.exceptions.GitHubAuthenticationException: Bad credentials
2023-12-15 21:58:26.202 ERROR (MainThread) [homeassistant.components.weather] Platform met does not generate unique IDs. ID home already exists - ignoring weather.forecast_home_assistant
2023-12-15 21:58:26.202 ERROR (MainThread) [homeassistant.components.weather] Platform met does not generate unique IDs. ID home already exists - ignoring weather.forecast_home_assistant
2023-12-15 21:58:26.605 WARNING (MainThread) [custom_components.xiaomi_miot] None device in xiaomi cloud: +79521183829
2023-12-15 21:58:36.307 WARNING (MainThread) [homeassistant.components.alarm_control_panel] Setup of alarm_control_panel platform xiaomi_miio is taking over 10 seconds.
2023-12-15 21:58:36.309 WARNING (MainThread) [homeassistant.components.light] Setup of light platform xiaomi_miio is taking over 10 seconds.
2023-12-15 21:58:42.565 ERROR (SyncWorker_7) [miio.miioprotocol] Got error when receiving: {'code': -9999, 'message': 'user ack timeout'}
2023-12-15 21:58:42.569 ERROR (SyncWorker_4) [miio.miioprotocol] Got error when receiving: {'code': -9999, 'message': 'user ack timeout'}
2023-12-15 21:58:42.571 ERROR (MainThread) [homeassistant.components.light] xiaomi_miio: Error on device update!
Traceback (most recent call last):
  File "/usr/local/lib/python3.11/site-packages/miio/miioprotocol.py", line 214, in send
    self._handle_error(payload["error"])
  File "/usr/local/lib/python3.11/site-packages/miio/miioprotocol.py", line 274, in _handle_error
    raise RecoverableError(error)
miio.exceptions.RecoverableError: {'code': -9999, 'message': 'user ack timeout'}

During handling of the above exception, another exception occurred:

Traceback (most recent call last):
  File "/usr/local/lib/python3.11/site-packages/miio/miioprotocol.py", line 214, in send
    self._handle_error(payload["error"])
  File "/usr/local/lib/python3.11/site-packages/miio/miioprotocol.py", line 274, in _handle_error
    raise RecoverableError(error)
miio.exceptions.RecoverableError: {'code': -9999, 'message': 'user ack timeout'}

During handling of the above exception, another exception occurred:

Traceback (most recent call last):
  File "/usr/local/lib/python3.11/site-packages/miio/miioprotocol.py", line 214, in send
    self._handle_error(payload["error"])
  File "/usr/local/lib/python3.11/site-packages/miio/miioprotocol.py", line 274, in _handle_error
    raise RecoverableError(error)
miio.exceptions.RecoverableError: {'code': -9999, 'message': 'user ack timeout'}

During handling of the above exception, another exception occurred:

Traceback (most recent call last):
  File "/usr/local/lib/python3.11/site-packages/miio/miioprotocol.py", line 214, in send
    self._handle_error(payload["error"])
  File "/usr/local/lib/python3.11/site-packages/miio/miioprotocol.py", line 274, in _handle_error
    raise RecoverableError(error)
miio.exceptions.RecoverableError: {'code': -9999, 'message': 'user ack timeout'}

The above exception was the direct cause of the following exception:

Traceback (most recent call last):
  File "/usr/src/homeassistant/homeassistant/helpers/entity_platform.py", line 575, in _async_add_entity
    await entity.async_device_update(warning=False)
  File "/usr/src/homeassistant/homeassistant/helpers/entity.py", line 959, in async_device_update
    await self.async_update()
  File "/usr/src/homeassistant/homeassistant/components/xiaomi_miio/light.py", line 1029, in async_update
    state_dict = await self.hass.async_add_executor_job(
                 ^^^^^^^^^^^^^^^^^^^^^^^^^^^^^^^^^^^^^^^
  File "/usr/local/lib/python3.11/concurrent/futures/thread.py", line 58, in run
    result = self.fn(*self.args, **self.kwargs)
             ^^^^^^^^^^^^^^^^^^^^^^^^^^^^^^^^^^
  File "/usr/local/lib/python3.11/site-packages/miio/gateway/light.py", line 39, in rgb_status
    state_int = self._gateway.send("get_rgb").pop()
                ^^^^^^^^^^^^^^^^^^^^^^^^^^^^^
  File "/usr/local/lib/python3.11/site-packages/miio/device.py", line 107, in send
    return self._protocol.send(
           ^^^^^^^^^^^^^^^^^^^^
  File "/usr/local/lib/python3.11/site-packages/miio/miioprotocol.py", line 248, in send
    return self.send(
           ^^^^^^^^^^
  File "/usr/local/lib/python3.11/site-packages/miio/miioprotocol.py", line 248, in send
    return self.send(
           ^^^^^^^^^^
  File "/usr/local/lib/python3.11/site-packages/miio/miioprotocol.py", line 248, in send
    return self.send(
           ^^^^^^^^^^
  File "/usr/local/lib/python3.11/site-packages/miio/miioprotocol.py", line 256, in send
    raise DeviceException("Unable to recover failed command") from ex
miio.exceptions.DeviceException: Unable to recover failed command
2023-12-15 21:58:42.885 ERROR (MainThread) [homeassistant.components.github] Bad credentials
Traceback (most recent call last):
  File "/usr/src/homeassistant/homeassistant/components/github/coordinator.py", line 128, in _async_update_data
    response = await self._client.graphql(
               ^^^^^^^^^^^^^^^^^^^^^^^^^^^
  File "/usr/local/lib/python3.11/site-packages/aiogithubapi/github.py", line 239, in graphql
    return await self._client.async_call_api(
           ^^^^^^^^^^^^^^^^^^^^^^^^^^^^^^^^^^
  File "/usr/local/lib/python3.11/site-packages/aiogithubapi/client.py", line 146, in async_call_api
    raise exception(message or response.data)
aiogithubapi.exceptions.GitHubAuthenticationException: Bad credentials
2023-12-15 21:58:53.345 ERROR (MainThread) [homeassistant.components.github] Bad credentials
Traceback (most recent call last):
  File "/usr/src/homeassistant/homeassistant/components/github/coordinator.py", line 128, in _async_update_data
    response = await self._client.graphql(
               ^^^^^^^^^^^^^^^^^^^^^^^^^^^
  File "/usr/local/lib/python3.11/site-packages/aiogithubapi/github.py", line 239, in graphql
    return await self._client.async_call_api(
           ^^^^^^^^^^^^^^^^^^^^^^^^^^^^^^^^^^
  File "/usr/local/lib/python3.11/site-packages/aiogithubapi/client.py", line 146, in async_call_api
    raise exception(message or response.data)
aiogithubapi.exceptions.GitHubAuthenticationException: Bad credentials
2023-12-15 21:59:06.312 WARNING (MainThread) [homeassistant.helpers.entity] Update of sensor.xiaomi_smart_home_hub_2_illuminance is taking over 10 seconds
2023-12-15 21:59:12.447 ERROR (SyncWorker_3) [miio.miioprotocol] Got error when receiving: {'code': -9999, 'message': 'user ack timeout'}
2023-12-15 21:59:13.825 ERROR (MainThread) [homeassistant.components.github] Bad credentials
Traceback (most recent call last):
  File "/usr/src/homeassistant/homeassistant/components/github/coordinator.py", line 128, in _async_update_data
    response = await self._client.graphql(
               ^^^^^^^^^^^^^^^^^^^^^^^^^^^
  File "/usr/local/lib/python3.11/site-packages/aiogithubapi/github.py", line 239, in graphql
    return await self._client.async_call_api(
           ^^^^^^^^^^^^^^^^^^^^^^^^^^^^^^^^^^
  File "/usr/local/lib/python3.11/site-packages/aiogithubapi/client.py", line 146, in async_call_api
    raise exception(message or response.data)
aiogithubapi.exceptions.GitHubAuthenticationException: Bad credentials
2023-12-15 21:59:22.573 WARNING (MainThread) [homeassistant.helpers.entity] Update of alarm_control_panel.xiaomi_smart_home_hub_2_alarm is taking over 10 seconds
2023-12-15 21:59:28.774 ERROR (SyncWorker_10) [miio.miioprotocol] Got error when receiving: {'code': -9999, 'message': 'user ack timeout'}
2023-12-15 21:59:35.646 ERROR (MainThread) [homeassistant.helpers.script.websocket_api_script] websocket_api script: Error executing script. Service not found for call_service at pos 1: Service shell_command.update_xiaomi_miot not found.
2023-12-15 21:59:35.646 ERROR (MainThread) [homeassistant.components.websocket_api.http.connection] [140572509933632] Error handling message: Service shell_command.update_xiaomi_miot not found. (home_assistant_error) relizerel161 from 192.168.1.67 (Mozilla/5.0 (Windows NT 10.0; Win64; x64) AppleWebKit/537.36 (KHTML, like Gecko) Chrome/120.0.0.0 Safari/537.36)
2023-12-15 21:59:36.313 WARNING (MainThread) [homeassistant.helpers.entity] Update of sensor.xiaomi_smart_home_hub_2_illuminance is taking over 10 seconds
2023-12-15 21:59:38.105 ERROR (MainThread) [homeassistant.helpers.script.websocket_api_script] websocket_api script: Error executing script. Service not found for call_service at pos 1: Service shell_command.update_xiaomi_miot not found.
2023-12-15 21:59:38.105 ERROR (MainThread) [homeassistant.components.websocket_api.http.connection] [140572509933632] Error handling message: Service shell_command.update_xiaomi_miot not found. (home_assistant_error) relizerel161 from 192.168.1.67 (Mozilla/5.0 (Windows NT 10.0; Win64; x64) AppleWebKit/537.36 (KHTML, like Gecko) Chrome/120.0.0.0 Safari/537.36)
2023-12-15 21:59:42.647 ERROR (SyncWorker_5) [miio.miioprotocol] Got error when receiving: {'code': -9999, 'message': 'user ack timeout'}
2023-12-15 21:59:52.575 WARNING (MainThread) [homeassistant.helpers.entity] Update of alarm_control_panel.xiaomi_smart_home_hub_2_alarm is taking over 10 seconds
2023-12-15 21:59:58.780 ERROR (SyncWorker_7) [miio.miioprotocol] Got error when receiving: {'code': -9999, 'message': 'user ack timeout'}
2023-12-15 22:00:06.314 WARNING (MainThread) [homeassistant.helpers.entity] Update of sensor.xiaomi_smart_home_hub_2_illuminance is taking over 10 seconds
2023-12-15 22:00:12.527 ERROR (SyncWorker_15) [miio.miioprotocol] Got error when receiving: {'code': -9999, 'message': 'user ack timeout'}
2023-12-15 22:00:22.575 WARNING (MainThread) [homeassistant.helpers.entity] Update of alarm_control_panel.xiaomi_smart_home_hub_2_alarm is taking over 10 seconds
2023-12-15 22:00:28.928 ERROR (SyncWorker_1) [miio.miioprotocol] Got error when receiving: {'code': -9999, 'message': 'user ack timeout'}
2023-12-15 22:00:36.313 WARNING (MainThread) [homeassistant.helpers.entity] Update of sensor.xiaomi_smart_home_hub_2_illuminance is taking over 10 seconds
2023-12-15 22:00:42.506 ERROR (SyncWorker_8) [miio.miioprotocol] Got error when receiving: {'code': -9999, 'message': 'user ack timeout'}
2023-12-15 22:00:52.575 WARNING (MainThread) [homeassistant.helpers.entity] Update of alarm_control_panel.xiaomi_smart_home_hub_2_alarm is taking over 10 seconds
2023-12-15 22:00:58.992 ERROR (SyncWorker_9) [miio.miioprotocol] Got error when receiving: {'code': -9999, 'message': 'user ack timeout'}
2023-12-15 22:01:06.315 WARNING (MainThread) [homeassistant.helpers.entity] Update of sensor.xiaomi_smart_home_hub_2_illuminance is taking over 10 seconds
2023-12-15 22:01:12.542 ERROR (SyncWorker_1) [miio.miioprotocol] Got error when receiving: {'code': -9999, 'message': 'user ack timeout'}
2023-12-15 22:01:22.575 WARNING (MainThread) [homeassistant.helpers.entity] Update of alarm_control_panel.xiaomi_smart_home_hub_2_alarm is taking over 10 seconds
2023-12-15 22:01:28.667 ERROR (SyncWorker_13) [miio.miioprotocol] Got error when receiving: {'code': -9999, 'message': 'user ack timeout'}
2023-12-15 22:01:36.316 WARNING (MainThread) [homeassistant.helpers.entity] Update of sensor.xiaomi_smart_home_hub_2_illuminance is taking over 10 seconds
2023-12-15 22:01:42.527 ERROR (SyncWorker_8) [miio.miioprotocol] Got error when receiving: {'code': -9999, 'message': 'user ack timeout'}
2023-12-15 22:01:52.576 WARNING (MainThread) [homeassistant.helpers.entity] Update of alarm_control_panel.xiaomi_smart_home_hub_2_alarm is taking over 10 seconds
2023-12-15 22:01:58.793 ERROR (SyncWorker_11) [miio.miioprotocol] Got error when receiving: {'code': -9999, 'message': 'user ack timeout'}
2023-12-15 22:02:06.317 WARNING (MainThread) [homeassistant.helpers.entity] Update of sensor.xiaomi_smart_home_hub_2_illuminance is taking over 10 seconds
2023-12-15 22:02:12.386 ERROR (SyncWorker_0) [miio.miioprotocol] Got error when receiving: {'code': -9999, 'message': 'user ack timeout'}
2023-12-15 22:02:22.577 WARNING (MainThread) [homeassistant.helpers.entity] Update of alarm_control_panel.xiaomi_smart_home_hub_2_alarm is taking over 10 seconds
2023-12-15 22:02:28.665 ERROR (SyncWorker_14) [miio.miioprotocol] Got error when receiving: {'code': -9999, 'message': 'user ack timeout'}
2023-12-15 22:02:36.317 WARNING (MainThread) [homeassistant.helpers.entity] Update of sensor.xiaomi_smart_home_hub_2_illuminance is taking over 10 seconds
2023-12-15 22:02:42.406 ERROR (SyncWorker_11) [miio.miioprotocol] Got error when receiving: {'code': -9999, 'message': 'user ack timeout'}
2023-12-15 22:02:52.578 WARNING (MainThread) [homeassistant.helpers.entity] Update of alarm_control_panel.xiaomi_smart_home_hub_2_alarm is taking over 10 seconds
2023-12-15 22:02:58.800 ERROR (SyncWorker_9) [miio.miioprotocol] Got error when receiving: {'code': -9999, 'message': 'user ack timeout'}
2023-12-15 22:03:06.319 WARNING (MainThread) [homeassistant.helpers.entity] Update of sensor.xiaomi_smart_home_hub_2_illuminance is taking over 10 seconds
2023-12-15 22:03:12.405 ERROR (SyncWorker_13) [miio.miioprotocol] Got error when receiving: {'code': -9999, 'message': 'user ack timeout'}
2023-12-15 22:03:22.579 WARNING (MainThread) [homeassistant.helpers.entity] Update of alarm_control_panel.xiaomi_smart_home_hub_2_alarm is taking over 10 seconds
2023-12-15 22:03:28.645 ERROR (SyncWorker_14) [miio.miioprotocol] Got error when receiving: {'code': -9999, 'message': 'user ack timeout'}
2023-12-15 22:03:36.320 WARNING (MainThread) [homeassistant.helpers.entity] Update of sensor.xiaomi_smart_home_hub_2_illuminance is taking over 10 seconds
2023-12-15 22:03:42.466 ERROR (SyncWorker_6) [miio.miioprotocol] Got error when receiving: {'code': -9999, 'message': 'user ack timeout'}
2023-12-15 22:03:52.580 WARNING (MainThread) [homeassistant.helpers.entity] Update of alarm_control_panel.xiaomi_smart_home_hub_2_alarm is taking over 10 seconds
2023-12-15 22:03:58.747 ERROR (SyncWorker_8) [miio.miioprotocol] Got error when receiving: {'code': -9999, 'message': 'user ack timeout'}
2023-12-15 22:04:06.320 WARNING (MainThread) [homeassistant.helpers.entity] Update of sensor.xiaomi_smart_home_hub_2_illuminance is taking over 10 seconds
2023-12-15 22:04:12.549 ERROR (SyncWorker_11) [miio.miioprotocol] Got error when receiving: {'code': -9999, 'message': 'user ack timeout'}
2023-12-15 22:04:22.580 WARNING (MainThread) [homeassistant.helpers.entity] Update of alarm_control_panel.xiaomi_smart_home_hub_2_alarm is taking over 10 seconds
2023-12-15 22:04:28.809 ERROR (SyncWorker_7) [miio.miioprotocol] Got error when receiving: {'code': -9999, 'message': 'user ack timeout'}
2023-12-15 22:04:36.323 WARNING (MainThread) [homeassistant.helpers.entity] Update of sensor.xiaomi_smart_home_hub_2_illuminance is taking over 10 seconds
2023-12-15 22:04:42.436 ERROR (SyncWorker_10) [miio.miioprotocol] Got error when receiving: {'code': -9999, 'message': 'user ack timeout'}
2023-12-15 22:04:52.581 WARNING (MainThread) [homeassistant.helpers.entity] Update of alarm_control_panel.xiaomi_smart_home_hub_2_alarm is taking over 10 seconds
2023-12-15 22:04:58.813 ERROR (SyncWorker_5) [miio.miioprotocol] Got error when receiving: {'code': -9999, 'message': 'user ack timeout'}
2023-12-15 22:05:06.323 WARNING (MainThread) [homeassistant.helpers.entity] Update of sensor.xiaomi_smart_home_hub_2_illuminance is taking over 10 seconds
2023-12-15 22:05:12.405 ERROR (SyncWorker_1) [miio.miioprotocol] Got error when receiving: {'code': -9999, 'message': 'user ack timeout'}
2023-12-15 22:05:22.582 WARNING (MainThread) [homeassistant.helpers.entity] Update of alarm_control_panel.xiaomi_smart_home_hub_2_alarm is taking over 10 seconds
2023-12-15 22:05:28.849 ERROR (SyncWorker_9) [miio.miioprotocol] Got error when receiving: {'code': -9999, 'message': 'user ack timeout'}
2023-12-15 22:05:36.325 WARNING (MainThread) [homeassistant.helpers.entity] Update of sensor.xiaomi_smart_home_hub_2_illuminance is taking over 10 seconds
2023-12-15 22:05:42.443 ERROR (SyncWorker_6) [miio.miioprotocol] Got error when receiving: {'code': -9999, 'message': 'user ack timeout'}
2023-12-15 22:05:52.583 WARNING (MainThread) [homeassistant.helpers.entity] Update of alarm_control_panel.xiaomi_smart_home_hub_2_alarm is taking over 10 seconds
2023-12-15 22:05:58.665 ERROR (SyncWorker_13) [miio.miioprotocol] Got error when receiving: {'code': -9999, 'message': 'user ack timeout'}
2023-12-15 22:06:05.339 ERROR (MainThread) [custom_components.xiaomi_miot.fan] Очиститель воздуха(zhimi.airpurifier.v7): Got MiioException while fetching the state: Unable to discover the device 192.168.1.71, mapping: {'air_purifier.on': {'siid': 2, 'piid': 1}, 'air_purifier.mode': {'siid': 2, 'piid': 2}, 'air_purifier.illumination': {'siid': 2, 'piid': 101}, 'air_purifier.motor_speed': {'siid': 2, 'piid': 102}, 'air_purifier.favorite_fan_level': {'siid': 2, 'piid': 103}, 'air_purifier.auto_detect': {'siid': 2, 'piid': 104}, 'indicator_light.on': {'siid': 7, 'piid': 1}, 'alarm': {'siid': 6, 'piid': 1}, 'physical_controls_locked': {'siid': 5, 'piid': 1}, 'filter.filter_life_level': {'siid': 4, 'piid': 1}, 'filter.filter_used_time': {'siid': 4, 'piid': 2}, 'environment.relative_humidity': {'siid': 3, 'piid': 1}, 'environment.pm2_5_density': {'siid': 3, 'piid': 2}, 'environment.temperature': {'siid': 3, 'piid': 3}}, max_properties: 10/14
2023-12-15 22:06:06.326 WARNING (MainThread) [homeassistant.helpers.entity] Update of sensor.xiaomi_smart_home_hub_2_illuminance is taking over 10 seconds
2023-12-15 22:06:12.485 ERROR (SyncWorker_8) [miio.miioprotocol] Got error when receiving: {'code': -9999, 'message': 'user ack timeout'}
2023-12-15 22:06:22.584 WARNING (MainThread) [homeassistant.helpers.entity] Update of alarm_control_panel.xiaomi_smart_home_hub_2_alarm is taking over 10 seconds
2023-12-15 22:06:28.722 ERROR (SyncWorker_12) [miio.miioprotocol] Got error when receiving: {'code': -9999, 'message': 'user ack timeout'}
2023-12-15 22:06:36.326 WARNING (MainThread) [homeassistant.helpers.entity] Update of sensor.xiaomi_smart_home_hub_2_illuminance is taking over 10 seconds
2023-12-15 22:06:40.356 ERROR (MainThread) [custom_components.xiaomi_miot.fan] Очиститель воздуха(zhimi.airpurifier.v7): Got MiioException while fetching the state: Unable to discover the device 192.168.1.71, mapping: {'air_purifier.on': {'siid': 2, 'piid': 1}, 'air_purifier.mode': {'siid': 2, 'piid': 2}, 'air_purifier.illumination': {'siid': 2, 'piid': 101}, 'air_purifier.motor_speed': {'siid': 2, 'piid': 102}, 'air_purifier.favorite_fan_level': {'siid': 2, 'piid': 103}, 'air_purifier.auto_detect': {'siid': 2, 'piid': 104}, 'indicator_light.on': {'siid': 7, 'piid': 1}, 'alarm': {'siid': 6, 'piid': 1}, 'physical_controls_locked': {'siid': 5, 'piid': 1}, 'filter.filter_life_level': {'siid': 4, 'piid': 1}, 'filter.filter_used_time': {'siid': 4, 'piid': 2}, 'environment.relative_humidity': {'siid': 3, 'piid': 1}, 'environment.pm2_5_density': {'siid': 3, 'piid': 2}, 'environment.temperature': {'siid': 3, 'piid': 3}}, max_properties: 10/14
2023-12-15 22:06:42.598 ERROR (SyncWorker_15) [miio.miioprotocol] Got error when receiving: {'code': -9999, 'message': 'user ack timeout'}
2023-12-15 22:06:52.585 WARNING (MainThread) [homeassistant.helpers.entity] Update of alarm_control_panel.xiaomi_smart_home_hub_2_alarm is taking over 10 seconds
2023-12-15 22:06:58.965 ERROR (SyncWorker_2) [miio.miioprotocol] Got error when receiving: {'code': -9999, 'message': 'user ack timeout'}
2023-12-15 22:07:06.327 WARNING (MainThread) [homeassistant.helpers.entity] Update of sensor.xiaomi_smart_home_hub_2_illuminance is taking over 10 seconds
2023-12-15 22:07:10.358 ERROR (MainThread) [custom_components.xiaomi_miot.fan] Очиститель воздуха(zhimi.airpurifier.v7): Got MiioException while fetching the state: Unable to discover the device 192.168.1.71, mapping: {'air_purifier.on': {'siid': 2, 'piid': 1}, 'air_purifier.mode': {'siid': 2, 'piid': 2}, 'air_purifier.illumination': {'siid': 2, 'piid': 101}, 'air_purifier.motor_speed': {'siid': 2, 'piid': 102}, 'air_purifier.favorite_fan_level': {'siid': 2, 'piid': 103}, 'air_purifier.auto_detect': {'siid': 2, 'piid': 104}, 'indicator_light.on': {'siid': 7, 'piid': 1}, 'alarm': {'siid': 6, 'piid': 1}, 'physical_controls_locked': {'siid': 5, 'piid': 1}, 'filter.filter_life_level': {'siid': 4, 'piid': 1}, 'filter.filter_used_time': {'siid': 4, 'piid': 2}, 'environment.relative_humidity': {'siid': 3, 'piid': 1}, 'environment.pm2_5_density': {'siid': 3, 'piid': 2}, 'environment.temperature': {'siid': 3, 'piid': 3}}, max_properties: 10/14
2023-12-15 22:07:12.550 ERROR (SyncWorker_5) [miio.miioprotocol] Got error when receiving: {'code': -9999, 'message': 'user ack timeout'}
2023-12-15 22:07:22.586 WARNING (MainThread) [homeassistant.helpers.entity] Update of alarm_control_panel.xiaomi_smart_home_hub_2_alarm is taking over 10 seconds
2023-12-15 22:07:28.730 ERROR (SyncWorker_14) [miio.miioprotocol] Got error when receiving: {'code': -9999, 'message': 'user ack timeout'}
2023-12-15 22:07:36.327 WARNING (MainThread) [homeassistant.helpers.entity] Update of sensor.xiaomi_smart_home_hub_2_illuminance is taking over 10 seconds
2023-12-15 22:07:40.358 ERROR (MainThread) [custom_components.xiaomi_miot.fan] Очиститель воздуха(zhimi.airpurifier.v7): Got MiioException while fetching the state: Unable to discover the device 192.168.1.71, mapping: {'air_purifier.on': {'siid': 2, 'piid': 1}, 'air_purifier.mode': {'siid': 2, 'piid': 2}, 'air_purifier.illumination': {'siid': 2, 'piid': 101}, 'air_purifier.motor_speed': {'siid': 2, 'piid': 102}, 'air_purifier.favorite_fan_level': {'siid': 2, 'piid': 103}, 'air_purifier.auto_detect': {'siid': 2, 'piid': 104}, 'indicator_light.on': {'siid': 7, 'piid': 1}, 'alarm': {'siid': 6, 'piid': 1}, 'physical_controls_locked': {'siid': 5, 'piid': 1}, 'filter.filter_life_level': {'siid': 4, 'piid': 1}, 'filter.filter_used_time': {'siid': 4, 'piid': 2}, 'environment.relative_humidity': {'siid': 3, 'piid': 1}, 'environment.pm2_5_density': {'siid': 3, 'piid': 2}, 'environment.temperature': {'siid': 3, 'piid': 3}}, max_properties: 10/14
2023-12-15 22:07:42.630 ERROR (SyncWorker_12) [miio.miioprotocol] Got error when receiving: {'code': -9999, 'message': 'user ack timeout'}
2023-12-15 22:07:52.588 WARNING (MainThread) [homeassistant.helpers.entity] Update of alarm_control_panel.xiaomi_smart_home_hub_2_alarm is taking over 10 seconds
2023-12-15 22:07:58.836 ERROR (SyncWorker_9) [miio.miioprotocol] Got error when receiving: {'code': -9999, 'message': 'user ack timeout'}
2023-12-15 22:08:06.328 WARNING (MainThread) [homeassistant.helpers.entity] Update of sensor.xiaomi_smart_home_hub_2_illuminance is taking over 10 seconds
2023-12-15 22:08:10.359 ERROR (MainThread) [custom_components.xiaomi_miot.fan] Очиститель воздуха(zhimi.airpurifier.v7): Got MiioException while fetching the state: Unable to discover the device 192.168.1.71, mapping: {'air_purifier.on': {'siid': 2, 'piid': 1}, 'air_purifier.mode': {'siid': 2, 'piid': 2}, 'air_purifier.illumination': {'siid': 2, 'piid': 101}, 'air_purifier.motor_speed': {'siid': 2, 'piid': 102}, 'air_purifier.favorite_fan_level': {'siid': 2, 'piid': 103}, 'air_purifier.auto_detect': {'siid': 2, 'piid': 104}, 'indicator_light.on': {'siid': 7, 'piid': 1}, 'alarm': {'siid': 6, 'piid': 1}, 'physical_controls_locked': {'siid': 5, 'piid': 1}, 'filter.filter_life_level': {'siid': 4, 'piid': 1}, 'filter.filter_used_time': {'siid': 4, 'piid': 2}, 'environment.relative_humidity': {'siid': 3, 'piid': 1}, 'environment.pm2_5_density': {'siid': 3, 'piid': 2}, 'environment.temperature': {'siid': 3, 'piid': 3}}, max_properties: 10/14
2023-12-15 22:08:12.405 ERROR (SyncWorker_1) [miio.miioprotocol] Got error when receiving: {'code': -9999, 'message': 'user ack timeout'}
2023-12-15 22:08:22.590 WARNING (MainThread) [homeassistant.helpers.entity] Update of alarm_control_panel.xiaomi_smart_home_hub_2_alarm is taking over 10 seconds
2023-12-15 22:08:28.837 ERROR (SyncWorker_12) [miio.miioprotocol] Got error when receiving: {'code': -9999, 'message': 'user ack timeout'}
2023-12-15 22:08:36.329 WARNING (MainThread) [homeassistant.helpers.entity] Update of sensor.xiaomi_smart_home_hub_2_illuminance is taking over 10 seconds
2023-12-15 22:08:40.360 ERROR (MainThread) [custom_components.xiaomi_miot.fan] Очиститель воздуха(zhimi.airpurifier.v7): Got MiioException while fetching the state: Unable to discover the device 192.168.1.71, mapping: {'air_purifier.on': {'siid': 2, 'piid': 1}, 'air_purifier.mode': {'siid': 2, 'piid': 2}, 'air_purifier.illumination': {'siid': 2, 'piid': 101}, 'air_purifier.motor_speed': {'siid': 2, 'piid': 102}, 'air_purifier.favorite_fan_level': {'siid': 2, 'piid': 103}, 'air_purifier.auto_detect': {'siid': 2, 'piid': 104}, 'indicator_light.on': {'siid': 7, 'piid': 1}, 'alarm': {'siid': 6, 'piid': 1}, 'physical_controls_locked': {'siid': 5, 'piid': 1}, 'filter.filter_life_level': {'siid': 4, 'piid': 1}, 'filter.filter_used_time': {'siid': 4, 'piid': 2}, 'environment.relative_humidity': {'siid': 3, 'piid': 1}, 'environment.pm2_5_density': {'siid': 3, 'piid': 2}, 'environment.temperature': {'siid': 3, 'piid': 3}}, max_properties: 10/14
2023-12-15 22:08:42.586 ERROR (SyncWorker_8) [miio.miioprotocol] Got error when receiving: {'code': -9999, 'message': 'user ack timeout'}
2023-12-15 22:08:52.589 WARNING (MainThread) [homeassistant.helpers.entity] Update of alarm_control_panel.xiaomi_smart_home_hub_2_alarm is taking over 10 seconds
2023-12-15 22:08:58.726 ERROR (SyncWorker_7) [miio.miioprotocol] Got error when receiving: {'code': -9999, 'message': 'user ack timeout'}
2023-12-15 22:09:06.330 WARNING (MainThread) [homeassistant.helpers.entity] Update of sensor.xiaomi_smart_home_hub_2_illuminance is taking over 10 seconds
2023-12-15 22:09:10.361 ERROR (MainThread) [custom_components.xiaomi_miot.fan] Очиститель воздуха(zhimi.airpurifier.v7): Got MiioException while fetching the state: Unable to discover the device 192.168.1.71, mapping: {'air_purifier.on': {'siid': 2, 'piid': 1}, 'air_purifier.mode': {'siid': 2, 'piid': 2}, 'air_purifier.illumination': {'siid': 2, 'piid': 101}, 'air_purifier.motor_speed': {'siid': 2, 'piid': 102}, 'air_purifier.favorite_fan_level': {'siid': 2, 'piid': 103}, 'air_purifier.auto_detect': {'siid': 2, 'piid': 104}, 'indicator_light.on': {'siid': 7, 'piid': 1}, 'alarm': {'siid': 6, 'piid': 1}, 'physical_controls_locked': {'siid': 5, 'piid': 1}, 'filter.filter_life_level': {'siid': 4, 'piid': 1}, 'filter.filter_used_time': {'siid': 4, 'piid': 2}, 'environment.relative_humidity': {'siid': 3, 'piid': 1}, 'environment.pm2_5_density': {'siid': 3, 'piid': 2}, 'environment.temperature': {'siid': 3, 'piid': 3}}, max_properties: 10/14
2023-12-15 22:09:12.587 ERROR (SyncWorker_0) [miio.miioprotocol] Got error when receiving: {'code': -9999, 'message': 'user ack timeout'}
2023-12-15 22:09:22.590 WARNING (MainThread) [homeassistant.helpers.entity] Update of alarm_control_panel.xiaomi_smart_home_hub_2_alarm is taking over 10 seconds
2023-12-15 22:09:28.706 ERROR (SyncWorker_15) [miio.miioprotocol] Got error when receiving: {'code': -9999, 'message': 'user ack timeout'}
2023-12-15 22:09:36.330 WARNING (MainThread) [homeassistant.helpers.entity] Update of sensor.xiaomi_smart_home_hub_2_illuminance is taking over 10 seconds
2023-12-15 22:09:40.361 ERROR (MainThread) [custom_components.xiaomi_miot.fan] Очиститель воздуха(zhimi.airpurifier.v7): Got MiioException while fetching the state: Unable to discover the device 192.168.1.71, mapping: {'air_purifier.on': {'siid': 2, 'piid': 1}, 'air_purifier.mode': {'siid': 2, 'piid': 2}, 'air_purifier.illumination': {'siid': 2, 'piid': 101}, 'air_purifier.motor_speed': {'siid': 2, 'piid': 102}, 'air_purifier.favorite_fan_level': {'siid': 2, 'piid': 103}, 'air_purifier.auto_detect': {'siid': 2, 'piid': 104}, 'indicator_light.on': {'siid': 7, 'piid': 1}, 'alarm': {'siid': 6, 'piid': 1}, 'physical_controls_locked': {'siid': 5, 'piid': 1}, 'filter.filter_life_level': {'siid': 4, 'piid': 1}, 'filter.filter_used_time': {'siid': 4, 'piid': 2}, 'environment.relative_humidity': {'siid': 3, 'piid': 1}, 'environment.pm2_5_density': {'siid': 3, 'piid': 2}, 'environment.temperature': {'siid': 3, 'piid': 3}}, max_properties: 10/14
2023-12-15 22:09:42.487 ERROR (SyncWorker_14) [miio.miioprotocol] Got error when receiving: {'code': -9999, 'message': 'user ack timeout'}
2023-12-15 22:09:52.590 WARNING (MainThread) [homeassistant.helpers.entity] Update of alarm_control_panel.xiaomi_smart_home_hub_2_alarm is taking over 10 seconds
2023-12-15 22:09:58.805 ERROR (SyncWorker_5) [miio.miioprotocol] Got error when receiving: {'code': -9999, 'message': 'user ack timeout'}
2023-12-15 22:10:06.330 WARNING (MainThread) [homeassistant.helpers.entity] Update of sensor.xiaomi_smart_home_hub_2_illuminance is taking over 10 seconds
2023-12-15 22:10:10.361 ERROR (MainThread) [custom_components.xiaomi_miot.fan] Очиститель воздуха(zhimi.airpurifier.v7): Got MiioException while fetching the state: Unable to discover the device 192.168.1.71, mapping: {'air_purifier.on': {'siid': 2, 'piid': 1}, 'air_purifier.mode': {'siid': 2, 'piid': 2}, 'air_purifier.illumination': {'siid': 2, 'piid': 101}, 'air_purifier.motor_speed': {'siid': 2, 'piid': 102}, 'air_purifier.favorite_fan_level': {'siid': 2, 'piid': 103}, 'air_purifier.auto_detect': {'siid': 2, 'piid': 104}, 'indicator_light.on': {'siid': 7, 'piid': 1}, 'alarm': {'siid': 6, 'piid': 1}, 'physical_controls_locked': {'siid': 5, 'piid': 1}, 'filter.filter_life_level': {'siid': 4, 'piid': 1}, 'filter.filter_used_time': {'siid': 4, 'piid': 2}, 'environment.relative_humidity': {'siid': 3, 'piid': 1}, 'environment.pm2_5_density': {'siid': 3, 'piid': 2}, 'environment.temperature': {'siid': 3, 'piid': 3}}, max_properties: 10/14
2023-12-15 22:10:12.572 ERROR (SyncWorker_7) [miio.miioprotocol] Got error when receiving: {'code': -9999, 'message': 'user ack timeout'}
2023-12-15 22:10:22.591 WARNING (MainThread) [homeassistant.helpers.entity] Update of alarm_control_panel.xiaomi_smart_home_hub_2_alarm is taking over 10 seconds
2023-12-15 22:10:29.807 ERROR (SyncWorker_15) [miio.miioprotocol] Got error when receiving: {'code': -9999, 'message': 'user ack timeout'}
2023-12-15 22:10:36.331 WARNING (MainThread) [homeassistant.helpers.entity] Update of sensor.xiaomi_smart_home_hub_2_illuminance is taking over 10 seconds
2023-12-15 22:10:40.362 ERROR (MainThread) [custom_components.xiaomi_miot.fan] Очиститель воздуха(zhimi.airpurifier.v7): Got MiioException while fetching the state: Unable to discover the device 192.168.1.71, mapping: {'air_purifier.on': {'siid': 2, 'piid': 1}, 'air_purifier.mode': {'siid': 2, 'piid': 2}, 'air_purifier.illumination': {'siid': 2, 'piid': 101}, 'air_purifier.motor_speed': {'siid': 2, 'piid': 102}, 'air_purifier.favorite_fan_level': {'siid': 2, 'piid': 103}, 'air_purifier.auto_detect': {'siid': 2, 'piid': 104}, 'indicator_light.on': {'siid': 7, 'piid': 1}, 'alarm': {'siid': 6, 'piid': 1}, 'physical_controls_locked': {'siid': 5, 'piid': 1}, 'filter.filter_life_level': {'siid': 4, 'piid': 1}, 'filter.filter_used_time': {'siid': 4, 'piid': 2}, 'environment.relative_humidity': {'siid': 3, 'piid': 1}, 'environment.pm2_5_density': {'siid': 3, 'piid': 2}, 'environment.temperature': {'siid': 3, 'piid': 3}}, max_properties: 10/14
2023-12-15 22:10:42.574 ERROR (SyncWorker_10) [miio.miioprotocol] Got error when receiving: {'code': -9999, 'message': 'user ack timeout'}
2023-12-15 22:10:52.592 WARNING (MainThread) [homeassistant.helpers.entity] Update of alarm_control_panel.xiaomi_smart_home_hub_2_alarm is taking over 10 seconds
2023-12-15 22:10:58.706 ERROR (SyncWorker_15) [miio.miioprotocol] Got error when receiving: {'code': -9999, 'message': 'user ack timeout'}
2023-12-15 22:11:06.331 WARNING (MainThread) [homeassistant.helpers.entity] Update of sensor.xiaomi_smart_home_hub_2_illuminance is taking over 10 seconds
2023-12-15 22:11:10.363 ERROR (MainThread) [custom_components.xiaomi_miot.fan] Очиститель воздуха(zhimi.airpurifier.v7): Got MiioException while fetching the state: Unable to discover the device 192.168.1.71, mapping: {'air_purifier.on': {'siid': 2, 'piid': 1}, 'air_purifier.mode': {'siid': 2, 'piid': 2}, 'air_purifier.illumination': {'siid': 2, 'piid': 101}, 'air_purifier.motor_speed': {'siid': 2, 'piid': 102}, 'air_purifier.favorite_fan_level': {'siid': 2, 'piid': 103}, 'air_purifier.auto_detect': {'siid': 2, 'piid': 104}, 'indicator_light.on': {'siid': 7, 'piid': 1}, 'alarm': {'siid': 6, 'piid': 1}, 'physical_controls_locked': {'siid': 5, 'piid': 1}, 'filter.filter_life_level': {'siid': 4, 'piid': 1}, 'filter.filter_used_time': {'siid': 4, 'piid': 2}, 'environment.relative_humidity': {'siid': 3, 'piid': 1}, 'environment.pm2_5_density': {'siid': 3, 'piid': 2}, 'environment.temperature': {'siid': 3, 'piid': 3}}, max_properties: 10/14
2023-12-15 22:11:12.478 ERROR (SyncWorker_3) [miio.miioprotocol] Got error when receiving: {'code': -9999, 'message': 'user ack timeout'}
2023-12-15 22:11:22.593 WARNING (MainThread) [homeassistant.helpers.entity] Update of alarm_control_panel.xiaomi_smart_home_hub_2_alarm is taking over 10 seconds
2023-12-15 22:11:28.706 ERROR (SyncWorker_8) [miio.miioprotocol] Got error when receiving: {'code': -9999, 'message': 'user ack timeout'}
2023-12-15 22:11:36.333 WARNING (MainThread) [homeassistant.helpers.entity] Update of sensor.xiaomi_smart_home_hub_2_illuminance is taking over 10 seconds
2023-12-15 22:11:40.364 ERROR (MainThread) [custom_components.xiaomi_miot.fan] Очиститель воздуха(zhimi.airpurifier.v7): Got MiioException while fetching the state: Unable to discover the device 192.168.1.71, mapping: {'air_purifier.on': {'siid': 2, 'piid': 1}, 'air_purifier.mode': {'siid': 2, 'piid': 2}, 'air_purifier.illumination': {'siid': 2, 'piid': 101}, 'air_purifier.motor_speed': {'siid': 2, 'piid': 102}, 'air_purifier.favorite_fan_level': {'siid': 2, 'piid': 103}, 'air_purifier.auto_detect': {'siid': 2, 'piid': 104}, 'indicator_light.on': {'siid': 7, 'piid': 1}, 'alarm': {'siid': 6, 'piid': 1}, 'physical_controls_locked': {'siid': 5, 'piid': 1}, 'filter.filter_life_level': {'siid': 4, 'piid': 1}, 'filter.filter_used_time': {'siid': 4, 'piid': 2}, 'environment.relative_humidity': {'siid': 3, 'piid': 1}, 'environment.pm2_5_density': {'siid': 3, 'piid': 2}, 'environment.temperature': {'siid': 3, 'piid': 3}}, max_properties: 10/14
2023-12-15 22:11:42.427 ERROR (SyncWorker_12) [miio.miioprotocol] Got error when receiving: {'code': -9999, 'message': 'user ack timeout'}
2023-12-15 22:11:52.595 WARNING (MainThread) [homeassistant.helpers.entity] Update of alarm_control_panel.xiaomi_smart_home_hub_2_alarm is taking over 10 seconds
2023-12-15 22:11:58.867 ERROR (SyncWorker_7) [miio.miioprotocol] Got error when receiving: {'code': -9999, 'message': 'user ack timeout'}
2023-12-15 22:12:06.336 WARNING (MainThread) [homeassistant.helpers.entity] Update of sensor.xiaomi_smart_home_hub_2_illuminance is taking over 10 seconds
2023-12-15 22:12:10.365 ERROR (MainThread) [custom_components.xiaomi_miot.fan] Очиститель воздуха(zhimi.airpurifier.v7): Got MiioException while fetching the state: Unable to discover the device 192.168.1.71, mapping: {'air_purifier.on': {'siid': 2, 'piid': 1}, 'air_purifier.mode': {'siid': 2, 'piid': 2}, 'air_purifier.illumination': {'siid': 2, 'piid': 101}, 'air_purifier.motor_speed': {'siid': 2, 'piid': 102}, 'air_purifier.favorite_fan_level': {'siid': 2, 'piid': 103}, 'air_purifier.auto_detect': {'siid': 2, 'piid': 104}, 'indicator_light.on': {'siid': 7, 'piid': 1}, 'alarm': {'siid': 6, 'piid': 1}, 'physical_controls_locked': {'siid': 5, 'piid': 1}, 'filter.filter_life_level': {'siid': 4, 'piid': 1}, 'filter.filter_used_time': {'siid': 4, 'piid': 2}, 'environment.relative_humidity': {'siid': 3, 'piid': 1}, 'environment.pm2_5_density': {'siid': 3, 'piid': 2}, 'environment.temperature': {'siid': 3, 'piid': 3}}, max_properties: 10/14
2023-12-15 22:12:12.414 ERROR (SyncWorker_2) [miio.miioprotocol] Got error when receiving: {'code': -9999, 'message': 'user ack timeout'}
2023-12-15 22:12:22.595 WARNING (MainThread) [homeassistant.helpers.entity] Update of alarm_control_panel.xiaomi_smart_home_hub_2_alarm is taking over 10 seconds
2023-12-15 22:12:28.726 ERROR (SyncWorker_1) [miio.miioprotocol] Got error when receiving: {'code': -9999, 'message': 'user ack timeout'}
2023-12-15 22:12:36.336 WARNING (MainThread) [homeassistant.helpers.entity] Update of sensor.xiaomi_smart_home_hub_2_illuminance is taking over 10 seconds
2023-12-15 22:12:40.365 ERROR (MainThread) [custom_components.xiaomi_miot.fan] Очиститель воздуха(zhimi.airpurifier.v7): Got MiioException while fetching the state: Unable to discover the device 192.168.1.71, mapping: {'air_purifier.on': {'siid': 2, 'piid': 1}, 'air_purifier.mode': {'siid': 2, 'piid': 2}, 'air_purifier.illumination': {'siid': 2, 'piid': 101}, 'air_purifier.motor_speed': {'siid': 2, 'piid': 102}, 'air_purifier.favorite_fan_level': {'siid': 2, 'piid': 103}, 'air_purifier.auto_detect': {'siid': 2, 'piid': 104}, 'indicator_light.on': {'siid': 7, 'piid': 1}, 'alarm': {'siid': 6, 'piid': 1}, 'physical_controls_locked': {'siid': 5, 'piid': 1}, 'filter.filter_life_level': {'siid': 4, 'piid': 1}, 'filter.filter_used_time': {'siid': 4, 'piid': 2}, 'environment.relative_humidity': {'siid': 3, 'piid': 1}, 'environment.pm2_5_density': {'siid': 3, 'piid': 2}, 'environment.temperature': {'siid': 3, 'piid': 3}}, max_properties: 10/14
2023-12-15 22:12:42.599 ERROR (SyncWorker_3) [miio.miioprotocol] Got error when receiving: {'code': -9999, 'message': 'user ack timeout'}
2023-12-15 22:12:52.596 WARNING (MainThread) [homeassistant.helpers.entity] Update of alarm_control_panel.xiaomi_smart_home_hub_2_alarm is taking over 10 seconds
2023-12-15 22:12:58.789 ERROR (SyncWorker_7) [miio.miioprotocol] Got error when receiving: {'code': -9999, 'message': 'user ack timeout'}
2023-12-15 22:13:06.337 WARNING (MainThread) [homeassistant.helpers.entity] Update of sensor.xiaomi_smart_home_hub_2_illuminance is taking over 10 seconds
2023-12-15 22:13:10.365 ERROR (MainThread) [custom_components.xiaomi_miot.fan] Очиститель воздуха(zhimi.airpurifier.v7): Got MiioException while fetching the state: Unable to discover the device 192.168.1.71, mapping: {'air_purifier.on': {'siid': 2, 'piid': 1}, 'air_purifier.mode': {'siid': 2, 'piid': 2}, 'air_purifier.illumination': {'siid': 2, 'piid': 101}, 'air_purifier.motor_speed': {'siid': 2, 'piid': 102}, 'air_purifier.favorite_fan_level': {'siid': 2, 'piid': 103}, 'air_purifier.auto_detect': {'siid': 2, 'piid': 104}, 'indicator_light.on': {'siid': 7, 'piid': 1}, 'alarm': {'siid': 6, 'piid': 1}, 'physical_controls_locked': {'siid': 5, 'piid': 1}, 'filter.filter_life_level': {'siid': 4, 'piid': 1}, 'filter.filter_used_time': {'siid': 4, 'piid': 2}, 'environment.relative_humidity': {'siid': 3, 'piid': 1}, 'environment.pm2_5_density': {'siid': 3, 'piid': 2}, 'environment.temperature': {'siid': 3, 'piid': 3}}, max_properties: 10/14
2023-12-15 22:13:12.494 ERROR (SyncWorker_4) [miio.miioprotocol] Got error when receiving: {'code': -9999, 'message': 'user ack timeout'}
2023-12-15 22:13:22.596 WARNING (MainThread) [homeassistant.helpers.entity] Update of alarm_control_panel.xiaomi_smart_home_hub_2_alarm is taking over 10 seconds
2023-12-15 22:13:28.698 ERROR (SyncWorker_7) [miio.miioprotocol] Got error when receiving: {'code': -9999, 'message': 'user ack timeout'}
2023-12-15 22:13:36.338 WARNING (MainThread) [homeassistant.helpers.entity] Update of sensor.xiaomi_smart_home_hub_2_illuminance is taking over 10 seconds
2023-12-15 22:13:40.367 ERROR (MainThread) [custom_components.xiaomi_miot.fan] Очиститель воздуха(zhimi.airpurifier.v7): Got MiioException while fetching the state: Unable to discover the device 192.168.1.71, mapping: {'air_purifier.on': {'siid': 2, 'piid': 1}, 'air_purifier.mode': {'siid': 2, 'piid': 2}, 'air_purifier.illumination': {'siid': 2, 'piid': 101}, 'air_purifier.motor_speed': {'siid': 2, 'piid': 102}, 'air_purifier.favorite_fan_level': {'siid': 2, 'piid': 103}, 'air_purifier.auto_detect': {'siid': 2, 'piid': 104}, 'indicator_light.on': {'siid': 7, 'piid': 1}, 'alarm': {'siid': 6, 'piid': 1}, 'physical_controls_locked': {'siid': 5, 'piid': 1}, 'filter.filter_life_level': {'siid': 4, 'piid': 1}, 'filter.filter_used_time': {'siid': 4, 'piid': 2}, 'environment.relative_humidity': {'siid': 3, 'piid': 1}, 'environment.pm2_5_density': {'siid': 3, 'piid': 2}, 'environment.temperature': {'siid': 3, 'piid': 3}}, max_properties: 10/14
2023-12-15 22:13:42.497 ERROR (SyncWorker_4) [miio.miioprotocol] Got error when receiving: {'code': -9999, 'message': 'user ack timeout'}
2023-12-15 22:13:52.596 WARNING (MainThread) [homeassistant.helpers.entity] Update of alarm_control_panel.xiaomi_smart_home_hub_2_alarm is taking over 10 seconds
2023-12-15 22:13:58.799 ERROR (SyncWorker_5) [miio.miioprotocol] Got error when receiving: {'code': -9999, 'message': 'user ack timeout'}
2023-12-15 22:14:06.339 WARNING (MainThread) [homeassistant.helpers.entity] Update of sensor.xiaomi_smart_home_hub_2_illuminance is taking over 10 seconds
2023-12-15 22:14:10.369 ERROR (MainThread) [custom_components.xiaomi_miot.fan] Очиститель воздуха(zhimi.airpurifier.v7): Got MiioException while fetching the state: Unable to discover the device 192.168.1.71, mapping: {'air_purifier.on': {'siid': 2, 'piid': 1}, 'air_purifier.mode': {'siid': 2, 'piid': 2}, 'air_purifier.illumination': {'siid': 2, 'piid': 101}, 'air_purifier.motor_speed': {'siid': 2, 'piid': 102}, 'air_purifier.favorite_fan_level': {'siid': 2, 'piid': 103}, 'air_purifier.auto_detect': {'siid': 2, 'piid': 104}, 'indicator_light.on': {'siid': 7, 'piid': 1}, 'alarm': {'siid': 6, 'piid': 1}, 'physical_controls_locked': {'siid': 5, 'piid': 1}, 'filter.filter_life_level': {'siid': 4, 'piid': 1}, 'filter.filter_used_time': {'siid': 4, 'piid': 2}, 'environment.relative_humidity': {'siid': 3, 'piid': 1}, 'environment.pm2_5_density': {'siid': 3, 'piid': 2}, 'environment.temperature': {'siid': 3, 'piid': 3}}, max_properties: 10/14
2023-12-15 22:14:12.438 ERROR (SyncWorker_4) [miio.miioprotocol] Got error when receiving: {'code': -9999, 'message': 'user ack timeout'}
2023-12-15 22:14:22.598 WARNING (MainThread) [homeassistant.helpers.entity] Update of alarm_control_panel.xiaomi_smart_home_hub_2_alarm is taking over 10 seconds
2023-12-15 22:14:40.370 ERROR (MainThread) [custom_components.xiaomi_miot.fan] Очиститель воздуха(zhimi.airpurifier.v7): Got MiioException while fetching the state: Unable to discover the device 192.168.1.71, mapping: {'air_purifier.on': {'siid': 2, 'piid': 1}, 'air_purifier.mode': {'siid': 2, 'piid': 2}, 'air_purifier.illumination': {'siid': 2, 'piid': 101}, 'air_purifier.motor_speed': {'siid': 2, 'piid': 102}, 'air_purifier.favorite_fan_level': {'siid': 2, 'piid': 103}, 'air_purifier.auto_detect': {'siid': 2, 'piid': 104}, 'indicator_light.on': {'siid': 7, 'piid': 1}, 'alarm': {'siid': 6, 'piid': 1}, 'physical_controls_locked': {'siid': 5, 'piid': 1}, 'filter.filter_life_level': {'siid': 4, 'piid': 1}, 'filter.filter_used_time': {'siid': 4, 'piid': 2}, 'environment.relative_humidity': {'siid': 3, 'piid': 1}, 'environment.pm2_5_density': {'siid': 3, 'piid': 2}, 'environment.temperature': {'siid': 3, 'piid': 3}}, max_properties: 10/14
2023-12-15 22:14:52.598 WARNING (MainThread) [homeassistant.helpers.entity] Update of alarm_control_panel.xiaomi_smart_home_hub_2_alarm is taking over 10 seconds
2023-12-15 22:14:58.864 ERROR (SyncWorker_6) [miio.miioprotocol] Got error when receiving: {'code': -9999, 'message': 'user ack timeout'}
2023-12-15 22:15:06.339 WARNING (MainThread) [homeassistant.helpers.entity] Update of sensor.xiaomi_smart_home_hub_2_illuminance is taking over 10 seconds
2023-12-15 22:15:10.368 ERROR (MainThread) [custom_components.xiaomi_miot.fan] Очиститель воздуха(zhimi.airpurifier.v7): Got MiioException while fetching the state: Unable to discover the device 192.168.1.71, mapping: {'air_purifier.on': {'siid': 2, 'piid': 1}, 'air_purifier.mode': {'siid': 2, 'piid': 2}, 'air_purifier.illumination': {'siid': 2, 'piid': 101}, 'air_purifier.motor_speed': {'siid': 2, 'piid': 102}, 'air_purifier.favorite_fan_level': {'siid': 2, 'piid': 103}, 'air_purifier.auto_detect': {'siid': 2, 'piid': 104}, 'indicator_light.on': {'siid': 7, 'piid': 1}, 'alarm': {'siid': 6, 'piid': 1}, 'physical_controls_locked': {'siid': 5, 'piid': 1}, 'filter.filter_life_level': {'siid': 4, 'piid': 1}, 'filter.filter_used_time': {'siid': 4, 'piid': 2}, 'environment.relative_humidity': {'siid': 3, 'piid': 1}, 'environment.pm2_5_density': {'siid': 3, 'piid': 2}, 'environment.temperature': {'siid': 3, 'piid': 3}}, max_properties: 10/14
2023-12-15 22:15:12.438 ERROR (SyncWorker_8) [miio.miioprotocol] Got error when receiving: {'code': -9999, 'message': 'user ack timeout'}
2023-12-15 22:15:22.602 WARNING (MainThread) [homeassistant.helpers.entity] Update of alarm_control_panel.xiaomi_smart_home_hub_2_alarm is taking over 10 seconds
2023-12-15 22:15:28.893 ERROR (SyncWorker_0) [miio.miioprotocol] Got error when receiving: {'code': -9999, 'message': 'user ack timeout'}
2023-12-15 22:15:36.341 WARNING (MainThread) [homeassistant.helpers.entity] Update of sensor.xiaomi_smart_home_hub_2_illuminance is taking over 10 seconds
2023-12-15 22:15:40.372 ERROR (MainThread) [custom_components.xiaomi_miot.fan] Очиститель воздуха(zhimi.airpurifier.v7): Got MiioException while fetching the state: Unable to discover the device 192.168.1.71, mapping: {'air_purifier.on': {'siid': 2, 'piid': 1}, 'air_purifier.mode': {'siid': 2, 'piid': 2}, 'air_purifier.illumination': {'siid': 2, 'piid': 101}, 'air_purifier.motor_speed': {'siid': 2, 'piid': 102}, 'air_purifier.favorite_fan_level': {'siid': 2, 'piid': 103}, 'air_purifier.auto_detect': {'siid': 2, 'piid': 104}, 'indicator_light.on': {'siid': 7, 'piid': 1}, 'alarm': {'siid': 6, 'piid': 1}, 'physical_controls_locked': {'siid': 5, 'piid': 1}, 'filter.filter_life_level': {'siid': 4, 'piid': 1}, 'filter.filter_used_time': {'siid': 4, 'piid': 2}, 'environment.relative_humidity': {'siid': 3, 'piid': 1}, 'environment.pm2_5_density': {'siid': 3, 'piid': 2}, 'environment.temperature': {'siid': 3, 'piid': 3}}, max_properties: 10/14
2023-12-15 22:15:42.457 ERROR (SyncWorker_5) [miio.miioprotocol] Got error when receiving: {'code': -9999, 'message': 'user ack timeout'}
2023-12-15 22:15:52.600 WARNING (MainThread) [homeassistant.helpers.entity] Update of alarm_control_panel.xiaomi_smart_home_hub_2_alarm is taking over 10 seconds
2023-12-15 22:15:58.918 ERROR (SyncWorker_2) [miio.miioprotocol] Got error when receiving: {'code': -9999, 'message': 'user ack timeout'}
2023-12-15 22:16:06.341 WARNING (MainThread) [homeassistant.helpers.entity] Update of sensor.xiaomi_smart_home_hub_2_illuminance is taking over 10 seconds
2023-12-15 22:16:10.373 ERROR (MainThread) [custom_components.xiaomi_miot.fan] Очиститель воздуха(zhimi.airpurifier.v7): Got MiioException while fetching the state: Unable to discover the device 192.168.1.71, mapping: {'air_purifier.on': {'siid': 2, 'piid': 1}, 'air_purifier.mode': {'siid': 2, 'piid': 2}, 'air_purifier.illumination': {'siid': 2, 'piid': 101}, 'air_purifier.motor_speed': {'siid': 2, 'piid': 102}, 'air_purifier.favorite_fan_level': {'siid': 2, 'piid': 103}, 'air_purifier.auto_detect': {'siid': 2, 'piid': 104}, 'indicator_light.on': {'siid': 7, 'piid': 1}, 'alarm': {'siid': 6, 'piid': 1}, 'physical_controls_locked': {'siid': 5, 'piid': 1}, 'filter.filter_life_level': {'siid': 4, 'piid': 1}, 'filter.filter_used_time': {'siid': 4, 'piid': 2}, 'environment.relative_humidity': {'siid': 3, 'piid': 1}, 'environment.pm2_5_density': {'siid': 3, 'piid': 2}, 'environment.temperature': {'siid': 3, 'piid': 3}}, max_properties: 10/14
2023-12-15 22:16:12.514 ERROR (SyncWorker_3) [miio.miioprotocol] Got error when receiving: {'code': -9999, 'message': 'user ack timeout'}
2023-12-15 22:16:22.601 WARNING (MainThread) [homeassistant.helpers.entity] Update of alarm_control_panel.xiaomi_smart_home_hub_2_alarm is taking over 10 seconds
2023-12-15 22:16:28.856 ERROR (SyncWorker_5) [miio.miioprotocol] Got error when receiving: {'code': -9999, 'message': 'user ack timeout'}
2023-12-15 22:16:36.342 WARNING (MainThread) [homeassistant.helpers.entity] Update of sensor.xiaomi_smart_home_hub_2_illuminance is taking over 10 seconds
2023-12-15 22:16:40.373 ERROR (MainThread) [custom_components.xiaomi_miot.fan] Очиститель воздуха(zhimi.airpurifier.v7): Got MiioException while fetching the state: Unable to discover the device 192.168.1.71, mapping: {'air_purifier.on': {'siid': 2, 'piid': 1}, 'air_purifier.mode': {'siid': 2, 'piid': 2}, 'air_purifier.illumination': {'siid': 2, 'piid': 101}, 'air_purifier.motor_speed': {'siid': 2, 'piid': 102}, 'air_purifier.favorite_fan_level': {'siid': 2, 'piid': 103}, 'air_purifier.auto_detect': {'siid': 2, 'piid': 104}, 'indicator_light.on': {'siid': 7, 'piid': 1}, 'alarm': {'siid': 6, 'piid': 1}, 'physical_controls_locked': {'siid': 5, 'piid': 1}, 'filter.filter_life_level': {'siid': 4, 'piid': 1}, 'filter.filter_used_time': {'siid': 4, 'piid': 2}, 'environment.relative_humidity': {'siid': 3, 'piid': 1}, 'environment.pm2_5_density': {'siid': 3, 'piid': 2}, 'environment.temperature': {'siid': 3, 'piid': 3}}, max_properties: 10/14
2023-12-15 22:16:42.517 ERROR (SyncWorker_9) [miio.miioprotocol] Got error when receiving: {'code': -9999, 'message': 'user ack timeout'}
2023-12-15 22:16:52.602 WARNING (MainThread) [homeassistant.helpers.entity] Update of alarm_control_panel.xiaomi_smart_home_hub_2_alarm is taking over 10 seconds
2023-12-15 22:16:59.004 ERROR (SyncWorker_8) [miio.miioprotocol] Got error when receiving: {'code': -9999, 'message': 'user ack timeout'}
2023-12-15 22:17:06.343 WARNING (MainThread) [homeassistant.helpers.entity] Update of sensor.xiaomi_smart_home_hub_2_illuminance is taking over 10 seconds
2023-12-15 22:17:10.373 ERROR (MainThread) [custom_components.xiaomi_miot.fan] Очиститель воздуха(zhimi.airpurifier.v7): Got MiioException while fetching the state: Unable to discover the device 192.168.1.71, mapping: {'air_purifier.on': {'siid': 2, 'piid': 1}, 'air_purifier.mode': {'siid': 2, 'piid': 2}, 'air_purifier.illumination': {'siid': 2, 'piid': 101}, 'air_purifier.motor_speed': {'siid': 2, 'piid': 102}, 'air_purifier.favorite_fan_level': {'siid': 2, 'piid': 103}, 'air_purifier.auto_detect': {'siid': 2, 'piid': 104}, 'indicator_light.on': {'siid': 7, 'piid': 1}, 'alarm': {'siid': 6, 'piid': 1}, 'physical_controls_locked': {'siid': 5, 'piid': 1}, 'filter.filter_life_level': {'siid': 4, 'piid': 1}, 'filter.filter_used_time': {'siid': 4, 'piid': 2}, 'environment.relative_humidity': {'siid': 3, 'piid': 1}, 'environment.pm2_5_density': {'siid': 3, 'piid': 2}, 'environment.temperature': {'siid': 3, 'piid': 3}}, max_properties: 10/14
2023-12-15 22:17:12.439 ERROR (SyncWorker_14) [miio.miioprotocol] Got error when receiving: {'code': -9999, 'message': 'user ack timeout'}
2023-12-15 22:17:22.604 WARNING (MainThread) [homeassistant.helpers.entity] Update of alarm_control_panel.xiaomi_smart_home_hub_2_alarm is taking over 10 seconds
2023-12-15 22:17:28.802 ERROR (SyncWorker_5) [miio.miioprotocol] Got error when receiving: {'code': -9999, 'message': 'user ack timeout'}
2023-12-15 22:17:36.344 WARNING (MainThread) [homeassistant.helpers.entity] Update of sensor.xiaomi_smart_home_hub_2_illuminance is taking over 10 seconds
2023-12-15 22:17:40.372 ERROR (MainThread) [custom_components.xiaomi_miot.fan] Очиститель воздуха(zhimi.airpurifier.v7): Got MiioException while fetching the state: Unable to discover the device 192.168.1.71, mapping: {'air_purifier.on': {'siid': 2, 'piid': 1}, 'air_purifier.mode': {'siid': 2, 'piid': 2}, 'air_purifier.illumination': {'siid': 2, 'piid': 101}, 'air_purifier.motor_speed': {'siid': 2, 'piid': 102}, 'air_purifier.favorite_fan_level': {'siid': 2, 'piid': 103}, 'air_purifier.auto_detect': {'siid': 2, 'piid': 104}, 'indicator_light.on': {'siid': 7, 'piid': 1}, 'alarm': {'siid': 6, 'piid': 1}, 'physical_controls_locked': {'siid': 5, 'piid': 1}, 'filter.filter_life_level': {'siid': 4, 'piid': 1}, 'filter.filter_used_time': {'siid': 4, 'piid': 2}, 'environment.relative_humidity': {'siid': 3, 'piid': 1}, 'environment.pm2_5_density': {'siid': 3, 'piid': 2}, 'environment.temperature': {'siid': 3, 'piid': 3}}, max_properties: 10/14
2023-12-15 22:17:42.524 ERROR (SyncWorker_0) [miio.miioprotocol] Got error when receiving: {'code': -9999, 'message': 'user ack timeout'}
2023-12-15 22:17:52.603 WARNING (MainThread) [homeassistant.helpers.entity] Update of alarm_control_panel.xiaomi_smart_home_hub_2_alarm is taking over 10 seconds
2023-12-15 22:17:58.806 ERROR (SyncWorker_12) [miio.miioprotocol] Got error when receiving: {'code': -9999, 'message': 'user ack timeout'}
2023-12-15 22:18:06.345 WARNING (MainThread) [homeassistant.helpers.entity] Update of sensor.xiaomi_smart_home_hub_2_illuminance is taking over 10 seconds
2023-12-15 22:18:10.375 ERROR (MainThread) [custom_components.xiaomi_miot.fan] Очиститель воздуха(zhimi.airpurifier.v7): Got MiioException while fetching the state: Unable to discover the device 192.168.1.71, mapping: {'air_purifier.on': {'siid': 2, 'piid': 1}, 'air_purifier.mode': {'siid': 2, 'piid': 2}, 'air_purifier.illumination': {'siid': 2, 'piid': 101}, 'air_purifier.motor_speed': {'siid': 2, 'piid': 102}, 'air_purifier.favorite_fan_level': {'siid': 2, 'piid': 103}, 'air_purifier.auto_detect': {'siid': 2, 'piid': 104}, 'indicator_light.on': {'siid': 7, 'piid': 1}, 'alarm': {'siid': 6, 'piid': 1}, 'physical_controls_locked': {'siid': 5, 'piid': 1}, 'filter.filter_life_level': {'siid': 4, 'piid': 1}, 'filter.filter_used_time': {'siid': 4, 'piid': 2}, 'environment.relative_humidity': {'siid': 3, 'piid': 1}, 'environment.pm2_5_density': {'siid': 3, 'piid': 2}, 'environment.temperature': {'siid': 3, 'piid': 3}}, max_properties: 10/14
2023-12-15 22:18:12.476 ERROR (SyncWorker_4) [miio.miioprotocol] Got error when receiving: {'code': -9999, 'message': 'user ack timeout'}
2023-12-15 22:18:22.603 WARNING (MainThread) [homeassistant.helpers.entity] Update of alarm_control_panel.xiaomi_smart_home_hub_2_alarm is taking over 10 seconds
2023-12-15 22:18:28.809 ERROR (SyncWorker_14) [miio.miioprotocol] Got error when receiving: {'code': -9999, 'message': 'user ack timeout'}
2023-12-15 22:18:36.345 WARNING (MainThread) [homeassistant.helpers.entity] Update of sensor.xiaomi_smart_home_hub_2_illuminance is taking over 10 seconds
2023-12-15 22:18:38.193 ERROR (MainThread) [homeassistant.config_entries] Error unloading entry Radio Browser for radio_browser
Traceback (most recent call last):
  File "/usr/src/homeassistant/homeassistant/config_entries.py", line 557, in async_unload
    result = await component.async_unload_entry(hass, self)
             ^^^^^^^^^^^^^^^^^^^^^^^^^^^^^^^^^^^^^^^^^^^^^^
  File "/usr/src/homeassistant/homeassistant/components/radio_browser/__init__.py", line 36, in async_unload_entry
    del hass.data[DOMAIN]
        ~~~~~~~~~^^^^^^^^
KeyError: 'radio_browser'
2023-12-15 22:18:40.376 ERROR (MainThread) [custom_components.xiaomi_miot.fan] Очиститель воздуха(zhimi.airpurifier.v7): Got MiioException while fetching the state: Unable to discover the device 192.168.1.71, mapping: {'air_purifier.on': {'siid': 2, 'piid': 1}, 'air_purifier.mode': {'siid': 2, 'piid': 2}, 'air_purifier.illumination': {'siid': 2, 'piid': 101}, 'air_purifier.motor_speed': {'siid': 2, 'piid': 102}, 'air_purifier.favorite_fan_level': {'siid': 2, 'piid': 103}, 'air_purifier.auto_detect': {'siid': 2, 'piid': 104}, 'indicator_light.on': {'siid': 7, 'piid': 1}, 'alarm': {'siid': 6, 'piid': 1}, 'physical_controls_locked': {'siid': 5, 'piid': 1}, 'filter.filter_life_level': {'siid': 4, 'piid': 1}, 'filter.filter_used_time': {'siid': 4, 'piid': 2}, 'environment.relative_humidity': {'siid': 3, 'piid': 1}, 'environment.pm2_5_density': {'siid': 3, 'piid': 2}, 'environment.temperature': {'siid': 3, 'piid': 3}}, max_properties: 10/14
2023-12-15 22:18:41.712 ERROR (MainThread) [homeassistant.config_entries] Error unloading entry Radio Browser for radio_browser
Traceback (most recent call last):
  File "/usr/src/homeassistant/homeassistant/config_entries.py", line 557, in async_unload
    result = await component.async_unload_entry(hass, self)
             ^^^^^^^^^^^^^^^^^^^^^^^^^^^^^^^^^^^^^^^^^^^^^^
  File "/usr/src/homeassistant/homeassistant/components/radio_browser/__init__.py", line 36, in async_unload_entry
    del hass.data[DOMAIN]
        ~~~~~~~~~^^^^^^^^
KeyError: 'radio_browser'
2023-12-15 22:18:42.531 ERROR (SyncWorker_1) [miio.miioprotocol] Got error when receiving: {'code': -9999, 'message': 'user ack timeout'}
2023-12-15 22:18:52.604 WARNING (MainThread) [homeassistant.helpers.entity] Update of alarm_control_panel.xiaomi_smart_home_hub_2_alarm is taking over 10 seconds
2023-12-15 22:18:58.705 ERROR (SyncWorker_13) [miio.miioprotocol] Got error when receiving: {'code': -9999, 'message': 'user ack timeout'}
2023-12-15 22:19:06.345 WARNING (MainThread) [homeassistant.helpers.entity] Update of sensor.xiaomi_smart_home_hub_2_illuminance is taking over 10 seconds
2023-12-15 22:19:10.377 ERROR (MainThread) [custom_components.xiaomi_miot.fan] Очиститель воздуха(zhimi.airpurifier.v7): Got MiioException while fetching the state: Unable to discover the device 192.168.1.71, mapping: {'air_purifier.on': {'siid': 2, 'piid': 1}, 'air_purifier.mode': {'siid': 2, 'piid': 2}, 'air_purifier.illumination': {'siid': 2, 'piid': 101}, 'air_purifier.motor_speed': {'siid': 2, 'piid': 102}, 'air_purifier.favorite_fan_level': {'siid': 2, 'piid': 103}, 'air_purifier.auto_detect': {'siid': 2, 'piid': 104}, 'indicator_light.on': {'siid': 7, 'piid': 1}, 'alarm': {'siid': 6, 'piid': 1}, 'physical_controls_locked': {'siid': 5, 'piid': 1}, 'filter.filter_life_level': {'siid': 4, 'piid': 1}, 'filter.filter_used_time': {'siid': 4, 'piid': 2}, 'environment.relative_humidity': {'siid': 3, 'piid': 1}, 'environment.pm2_5_density': {'siid': 3, 'piid': 2}, 'environment.temperature': {'siid': 3, 'piid': 3}}, max_properties: 10/14
2023-12-15 22:19:12.610 ERROR (SyncWorker_2) [miio.miioprotocol] Got error when receiving: {'code': -9999, 'message': 'user ack timeout'}
2023-12-15 22:19:22.605 WARNING (MainThread) [homeassistant.helpers.entity] Update of alarm_control_panel.xiaomi_smart_home_hub_2_alarm is taking over 10 seconds
2023-12-15 22:19:28.919 ERROR (SyncWorker_4) [miio.miioprotocol] Got error when receiving: {'code': -9999, 'message': 'user ack timeout'}
2023-12-15 22:19:36.347 WARNING (MainThread) [homeassistant.helpers.entity] Update of sensor.xiaomi_smart_home_hub_2_illuminance is taking over 10 seconds
2023-12-15 22:19:40.379 ERROR (MainThread) [custom_components.xiaomi_miot.fan] Очиститель воздуха(zhimi.airpurifier.v7): Got MiioException while fetching the state: Unable to discover the device 192.168.1.71, mapping: {'air_purifier.on': {'siid': 2, 'piid': 1}, 'air_purifier.mode': {'siid': 2, 'piid': 2}, 'air_purifier.illumination': {'siid': 2, 'piid': 101}, 'air_purifier.motor_speed': {'siid': 2, 'piid': 102}, 'air_purifier.favorite_fan_level': {'siid': 2, 'piid': 103}, 'air_purifier.auto_detect': {'siid': 2, 'piid': 104}, 'indicator_light.on': {'siid': 7, 'piid': 1}, 'alarm': {'siid': 6, 'piid': 1}, 'physical_controls_locked': {'siid': 5, 'piid': 1}, 'filter.filter_life_level': {'siid': 4, 'piid': 1}, 'filter.filter_used_time': {'siid': 4, 'piid': 2}, 'environment.relative_humidity': {'siid': 3, 'piid': 1}, 'environment.pm2_5_density': {'siid': 3, 'piid': 2}, 'environment.temperature': {'siid': 3, 'piid': 3}}, max_properties: 10/14
2023-12-15 22:19:42.592 ERROR (SyncWorker_3) [miio.miioprotocol] Got error when receiving: {'code': -9999, 'message': 'user ack timeout'}
2023-12-15 22:19:52.605 WARNING (MainThread) [homeassistant.helpers.entity] Update of alarm_control_panel.xiaomi_smart_home_hub_2_alarm is taking over 10 seconds
2023-12-15 22:19:58.820 ERROR (SyncWorker_1) [miio.miioprotocol] Got error when receiving: {'code': -9999, 'message': 'user ack timeout'}
2023-12-15 22:20:06.349 WARNING (MainThread) [homeassistant.helpers.entity] Update of sensor.xiaomi_smart_home_hub_2_illuminance is taking over 10 seconds
2023-12-15 22:20:09.481 WARNING (MainThread) [homeassistant.helpers.entity] Update of humidifier.viomi_v9_2720_humidifier is taking over 10 seconds
2023-12-15 22:20:10.379 ERROR (MainThread) [custom_components.xiaomi_miot.fan] Очиститель воздуха(zhimi.airpurifier.v7): Got MiioException while fetching the state: Unable to discover the device 192.168.1.71, mapping: {'air_purifier.on': {'siid': 2, 'piid': 1}, 'air_purifier.mode': {'siid': 2, 'piid': 2}, 'air_purifier.illumination': {'siid': 2, 'piid': 101}, 'air_purifier.motor_speed': {'siid': 2, 'piid': 102}, 'air_purifier.favorite_fan_level': {'siid': 2, 'piid': 103}, 'air_purifier.auto_detect': {'siid': 2, 'piid': 104}, 'indicator_light.on': {'siid': 7, 'piid': 1}, 'alarm': {'siid': 6, 'piid': 1}, 'physical_controls_locked': {'siid': 5, 'piid': 1}, 'filter.filter_life_level': {'siid': 4, 'piid': 1}, 'filter.filter_used_time': {'siid': 4, 'piid': 2}, 'environment.relative_humidity': {'siid': 3, 'piid': 1}, 'environment.pm2_5_density': {'siid': 3, 'piid': 2}, 'environment.temperature': {'siid': 3, 'piid': 3}}, max_properties: 10/14
2023-12-15 22:20:12.625 ERROR (SyncWorker_4) [miio.miioprotocol] Got error when receiving: {'code': -9999, 'message': 'user ack timeout'}
2023-12-15 22:20:22.606 WARNING (MainThread) [homeassistant.helpers.entity] Update of alarm_control_panel.xiaomi_smart_home_hub_2_alarm is taking over 10 seconds
2023-12-15 22:20:28.821 ERROR (SyncWorker_7) [miio.miioprotocol] Got error when receiving: {'code': -9999, 'message': 'user ack timeout'}
2023-12-15 22:20:36.348 WARNING (MainThread) [homeassistant.helpers.entity] Update of sensor.xiaomi_smart_home_hub_2_illuminance is taking over 10 seconds
2023-12-15 22:20:40.380 ERROR (MainThread) [custom_components.xiaomi_miot.fan] Очиститель воздуха(zhimi.airpurifier.v7): Got MiioException while fetching the state: Unable to discover the device 192.168.1.71, mapping: {'air_purifier.on': {'siid': 2, 'piid': 1}, 'air_purifier.mode': {'siid': 2, 'piid': 2}, 'air_purifier.illumination': {'siid': 2, 'piid': 101}, 'air_purifier.motor_speed': {'siid': 2, 'piid': 102}, 'air_purifier.favorite_fan_level': {'siid': 2, 'piid': 103}, 'air_purifier.auto_detect': {'siid': 2, 'piid': 104}, 'indicator_light.on': {'siid': 7, 'piid': 1}, 'alarm': {'siid': 6, 'piid': 1}, 'physical_controls_locked': {'siid': 5, 'piid': 1}, 'filter.filter_life_level': {'siid': 4, 'piid': 1}, 'filter.filter_used_time': {'siid': 4, 'piid': 2}, 'environment.relative_humidity': {'siid': 3, 'piid': 1}, 'environment.pm2_5_density': {'siid': 3, 'piid': 2}, 'environment.temperature': {'siid': 3, 'piid': 3}}, max_properties: 10/14
2023-12-15 22:20:42.875 ERROR (SyncWorker_9) [miio.miioprotocol] Got error when receiving: {'code': -9999, 'message': 'user ack timeout'}
2023-12-15 22:20:51.609 WARNING (MainThread) [custom_components.xiaomi_miot] None device in xiaomi cloud: +79521183829
2023-12-15 22:20:52.606 WARNING (MainThread) [homeassistant.helpers.entity] Update of alarm_control_panel.xiaomi_smart_home_hub_2_alarm is taking over 10 seconds
2023-12-15 22:20:56.768 ERROR (MainThread) [custom_components.xiaomi_miot.fan] Очиститель воздуха(zhimi.airpurifier.v7): Got MiioException while fetching the state: Unable to discover the device 192.168.1.71, mapping: {'air_purifier.on': {'siid': 2, 'piid': 1}, 'air_purifier.mode': {'siid': 2, 'piid': 2}, 'air_purifier.illumination': {'siid': 2, 'piid': 101}, 'air_purifier.motor_speed': {'siid': 2, 'piid': 102}, 'air_purifier.favorite_fan_level': {'siid': 2, 'piid': 103}, 'air_purifier.auto_detect': {'siid': 2, 'piid': 104}, 'indicator_light.on': {'siid': 7, 'piid': 1}, 'alarm': {'siid': 6, 'piid': 1}, 'physical_controls_locked': {'siid': 5, 'piid': 1}, 'filter.filter_life_level': {'siid': 4, 'piid': 1}, 'filter.filter_used_time': {'siid': 4, 'piid': 2}, 'environment.relative_humidity': {'siid': 3, 'piid': 1}, 'environment.pm2_5_density': {'siid': 3, 'piid': 2}, 'environment.temperature': {'siid': 3, 'piid': 3}}, max_properties: 10/14
2023-12-15 22:20:58.724 ERROR (SyncWorker_2) [miio.miioprotocol] Got error when receiving: {'code': -9999, 'message': 'user ack timeout'}
2023-12-15 22:21:06.349 WARNING (MainThread) [homeassistant.helpers.entity] Update of sensor.xiaomi_smart_home_hub_2_illuminance is taking over 10 seconds
2023-12-15 22:21:12.555 ERROR (SyncWorker_0) [miio.miioprotocol] Got error when receiving: {'code': -9999, 'message': 'user ack timeout'}
2023-12-15 22:21:22.607 WARNING (MainThread) [homeassistant.helpers.entity] Update of alarm_control_panel.xiaomi_smart_home_hub_2_alarm is taking over 10 seconds
2023-12-15 22:21:28.717 ERROR (SyncWorker_2) [miio.miioprotocol] Got error when receiving: {'code': -9999, 'message': 'user ack timeout'}
2023-12-15 22:21:31.779 ERROR (MainThread) [custom_components.xiaomi_miot.fan] Очиститель воздуха(zhimi.airpurifier.v7): Got MiioException while fetching the state: Unable to discover the device 192.168.1.71, mapping: {'air_purifier.on': {'siid': 2, 'piid': 1}, 'air_purifier.mode': {'siid': 2, 'piid': 2}, 'air_purifier.illumination': {'siid': 2, 'piid': 101}, 'air_purifier.motor_speed': {'siid': 2, 'piid': 102}, 'air_purifier.favorite_fan_level': {'siid': 2, 'piid': 103}, 'air_purifier.auto_detect': {'siid': 2, 'piid': 104}, 'indicator_light.on': {'siid': 7, 'piid': 1}, 'alarm': {'siid': 6, 'piid': 1}, 'physical_controls_locked': {'siid': 5, 'piid': 1}, 'filter.filter_life_level': {'siid': 4, 'piid': 1}, 'filter.filter_used_time': {'siid': 4, 'piid': 2}, 'environment.relative_humidity': {'siid': 3, 'piid': 1}, 'environment.pm2_5_density': {'siid': 3, 'piid': 2}, 'environment.temperature': {'siid': 3, 'piid': 3}}, max_properties: 10/14
2023-12-15 22:21:36.352 WARNING (MainThread) [homeassistant.helpers.entity] Update of sensor.xiaomi_smart_home_hub_2_illuminance is taking over 10 seconds
2023-12-15 22:21:42.606 ERROR (SyncWorker_4) [miio.miioprotocol] Got error when receiving: {'code': -9999, 'message': 'user ack timeout'}
2023-12-15 22:21:52.609 WARNING (MainThread) [homeassistant.helpers.entity] Update of alarm_control_panel.xiaomi_smart_home_hub_2_alarm is taking over 10 seconds
2023-12-15 22:21:58.745 ERROR (SyncWorker_5) [miio.miioprotocol] Got error when receiving: {'code': -9999, 'message': 'user ack timeout'}
2023-12-15 22:22:01.781 ERROR (MainThread) [custom_components.xiaomi_miot.fan] Очиститель воздуха(zhimi.airpurifier.v7): Got MiioException while fetching the state: Unable to discover the device 192.168.1.71, mapping: {'air_purifier.on': {'siid': 2, 'piid': 1}, 'air_purifier.mode': {'siid': 2, 'piid': 2}, 'air_purifier.illumination': {'siid': 2, 'piid': 101}, 'air_purifier.motor_speed': {'siid': 2, 'piid': 102}, 'air_purifier.favorite_fan_level': {'siid': 2, 'piid': 103}, 'air_purifier.auto_detect': {'siid': 2, 'piid': 104}, 'indicator_light.on': {'siid': 7, 'piid': 1}, 'alarm': {'siid': 6, 'piid': 1}, 'physical_controls_locked': {'siid': 5, 'piid': 1}, 'filter.filter_life_level': {'siid': 4, 'piid': 1}, 'filter.filter_used_time': {'siid': 4, 'piid': 2}, 'environment.relative_humidity': {'siid': 3, 'piid': 1}, 'environment.pm2_5_density': {'siid': 3, 'piid': 2}, 'environment.temperature': {'siid': 3, 'piid': 3}}, max_properties: 10/14
2023-12-15 22:22:06.350 WARNING (MainThread) [homeassistant.helpers.entity] Update of sensor.xiaomi_smart_home_hub_2_illuminance is taking over 10 seconds
